Workbook

Sheet revenue_build
A1: SERVICENOW (NOW) — REVENUE BUILD & SOFTWARE KPIs
A2: ($ in millions, unless noted)
B3: FY2022A | C3: FY2023A | D3: FY2024A | E3: FY2025E | F3: FY2026E | G3: FY2027E
A4: ANNUAL RECURRING REVENUE (ARR) BRIDGE
A5: Beginning ARR | B5: 5737 | C5: =B10 | D5: =C10 | E5: =D10 | F5: =E10 | G5: =F10
A6: + New Logo ARR | B6: 200 | C6: 250 | D6: 300 | E6: =D6*(1+Assumptions!$B$34) | F6: =E6*(1+Assumptions!$C$34) | G6: =F6*(1+Assumptions!$D$34)
A7: + Expansion ARR | B7: 1237 | C7: 1712 | D7: 1747 | E7: =E5*Assumptions!$B$35 | F7: =F5*Assumptions!$C$35 | G7: =G5*Assumptions!$D$35
A8: − Contraction ARR | B8: -17 | C8: -21 | D8: -27 | E8: =-E5*Assumptions!$B$37 | F8: =-F5*Assumptions!$C$37 | G8: =-G5*Assumptions!$D$37
A9: − Churned ARR | B9: -57 | C9: -71 | D9: -90 | E9: =-E5*(1-Assumptions!$B$36) | F9: =-F5*(1-Assumptions!$C$36) | G9: =-G5*(1-Assumptions!$D$36)
A10: Ending ARR | B10: =B5+B6+B7+B8+B9 | C10: =C5+C6+C7+C8+C9 | D10: =D5+D6+D7+D8+D9 | E10: =E5+E6+E7+E8+E9 | F10: =F5+F6+F7+F8+F9 | G10: =G5+G6+G7+G8+G9
A11: ARR Growth % | C11: =C10/B10-1 | D11: =D10/C10-1 | E11: =E10/D10-1 | F11: =F10/E10-1 | G11: =G10/F10-1
A12: Implied ARR per Customer ($K) | B12: =B10/B32*1000 | C12: =C10/C32*1000 | D12: =D10/D32*1000 | E12: =E10/E32*1000 | F12: =F10/F32*1000 | G12: =G10/G32*1000
A14: RETENTION METRICS
A15: Gross Revenue Retention (GRR) % | B15: 0.99 | C15: 0.99 | D15: 0.99 | E15: =Assumptions!$B$36 | F15: =Assumptions!$C$36 | G15: =Assumptions!$D$36
A16: Net Revenue Retention (NRR) % | B16: 1.27 | C16: 1.26 | D16: 1.25 | E16: =Assumptions!$B$41 | F16: =Assumptions!$C$41 | G16: =Assumptions!$D$41
A17: Gross Churn Rate % | B17: =1-B15 | C17: =1-C15 | D17: =1-D15 | E17: =1-E15 | F17: =1-F15 | G17: =1-G15
A18: Net Expansion Rate % | B18: =B16-B15 | C18: =C16-C15 | D18: =D16-D15 | E18: =E16-E15 | F18: =F16-F15 | G18: =G16-G15
A19: Logo Churn Rate % | B19: 0.03 | C19: 0.03 | D19: 0.03 | E19: =Assumptions!$B$42 | F19: =Assumptions!$C$42 | G19: =Assumptions!$D$42
A21: REMAINING PERFORMANCE OBLIGATIONS (RPO)
A22: Total RPO | B22: 13600 | C22: 17700 | D22: 21900 | E22: =D22*(1+Assumptions!$B$51) | F22: =E22*(1+Assumptions!$C$51) | G22: =F22*(1+Assumptions!$D$51)
A23: Current RPO (cRPO) | B23: 7000 | C23: 8300 | D23: 10300 | E23: =E22*Assumptions!$B$52 | F23: =F22*Assumptions!$C$52 | G23: =G22*Assumptions!$D$52
A24: Non-Current RPO | B24: =B22-B23 | C24: =C22-C23 | D24: =D22-D23 | E24: =E22-E23 | F24: =F22-F23 | G24: =G22-G23
A25: cRPO / Total RPO % | B25: =B23/B22 | C25: =C23/C22 | D25: =D23/D22 | E25: =E23/E22 | F25: =F23/F22 | G25: =G23/G22
A26: Total RPO Growth % | C26: =C22/B22-1 | D26: =D22/C22-1 | E26: =E22/D22-1 | F26: =F22/E22-1 | G26: =G22/F22-1
A28: CUSTOMER METRICS — BY ACV TIER
A29: Customers > $1M ACV | B29: 1530 | C29: 1986 | D29: 2550 | E29: =D29*(1+Assumptions!$B$45) | F29: =E29*(1+Assumptions!$C$45) | G29: =F29*(1+Assumptions!$D$45)
A30: Customers > $5M ACV | B30: 156 | C30: 197 | D30: 243 | E30: =D30*(1+Assumptions!$B$46) | F30: =E30*(1+Assumptions!$C$46) | G30: =F30*(1+Assumptions!$D$46)
A31: Customers > $20M ACV | B31: 74 | C31: 92 | D31: 114 | E31: =D31*(1+Assumptions!$B$47) | F31: =E31*(1+Assumptions!$C$47) | G31: =F31*(1+Assumptions!$D$47)
A32: Total Enterprise Customers | B32: 7400 | C32: 8100 | D32: 8800 | E32: =D32*(1+Assumptions!$B$45*0.6) | F32: =E32*(1+Assumptions!$C$45*0.6) | G32: =F32*(1+Assumptions!$D$45*0.6)
A33: YoY Growth — Customers >$1M | C33: =C29/B29-1 | D33: =D29/C29-1 | E33: =E29/D29-1 | F33: =F29/E29-1 | G33: =G29/F29-1
A34: YoY Growth — Customers >$5M | C34: =C30/B30-1 | D34: =D30/C30-1 | E34: =E30/D30-1 | F34: =F30/E30-1 | G34: =G30/F30-1
A36: REVENUE METRICS
A37: Subscription Revenue | B37: 6894 | C37: 8396 | D37: 10402 | E37: =E46 | F37: =F46 | G37: =G46
A38: Professional Services Revenue | B38: 586 | C38: 537 | D38: 576 | E38: =E37*Assumptions!$B$55 | F38: =F37*Assumptions!$C$55 | G38: =G37*Assumptions!$D$55
A39: Total Revenue | B39: =B37+B38 | C39: =C37+C38 | D39: =D37+D38 | E39: =E37+E38 | F39: =F37+F38 | G39: =G37+G38
A40: Subscription Revenue Growth % | C40: =C37/B37-1 | D40: =D37/C37-1 | E40: =E37/D37-1 | F40: =F37/E37-1 | G40: =G37/F37-1
A41: Implied Billings | B41: =B10-B5+B37 | C41: =C10-C5+C37 | D41: =D10-D5+D37 | E41: =E10-E5+E37 | F41: =F10-F5+F37 | G41: =G10-G5+G37
A43: PRIMARY FORECAST METHODOLOGY: ARR Bridge
A44: Average ARR ((Beg + End) / 2) | B44: =(B5+B10)/2 | C44: =(C5+C10)/2 | D44: =(D5+D10)/2 | E44: =(E5+E10)/2 | F44: =(F5+F10)/2 | G44: =(G5+G10)/2
A45: Billing Timing Factor | B45: =B37/B44 | C45: =C37/C44 | D45: =D37/D44 | E45: =Assumptions!$B$38 | F45: =Assumptions!$C$38 | G45: =Assumptions!$D$38
...

Sheet IS
A1: SERVICENOW (NOW) — INCOME STATEMENT
A2: ($ in millions)
B3: FY2022A | C3: FY2023A | D3: FY2024A | E3: FY2025E | F3: FY2026E | G3: FY2027E
A4: REVENUE
A5: Subscription Revenue | B5: 6894 | C5: 8396 | D5: 10402 | E5: =revenue_build!E37 | F5: =revenue_build!F37 | G5: =revenue_build!G37
A6: Professional Services Revenue | B6: 586 | C6: 537 | D6: 576 | E6: =revenue_build!E38 | F6: =revenue_build!F38 | G6: =revenue_build!G38
A7: Total Revenue | B7: =B5+B6 | C7: =C5+C6 | D7: =D5+D6 | E7: =E5+E6 | F7: =F5+F6 | G7: =G5+G6
A8: Revenue Growth % | C8: =C7/B7-1 | D8: =D7/C7-1 | E8: =E7/D7-1 | F8: =F7/E7-1 | G8: =G7/F7-1
A10: COST OF REVENUE
A11: Cost of Revenue — Subscription | B11: 1211 | C11: 1431 | D11: 1740 | E11: =E13*0.75 | F11: =F13*0.75 | G11: =G13*0.75
A12: Cost of Revenue — Professional Services | B12: 543 | C12: 513 | D12: 567 | E12: =E13*0.25 | F12: =F13*0.25 | G12: =G13*0.25
A13: Total Cost of Revenue | B13: =B11+B12 | C13: =C11+C12 | D13: =D11+D12 | E13: =E7*(1-Assumptions!$B$6) | F13: =F7*(1-Assumptions!$C$6) | G13: =G7*(1-Assumptions!$D$6)
A14: Gross Profit | B14: =B7-B13 | C14: =C7-C13 | D14: =D7-D13 | E14: =E7-E13 | F14: =F7-F13 | G14: =G7-G13
A15: Gross Margin % | B15: =B14/B7 | C15: =C14/C7 | D15: =D14/D7 | E15: =E14/E7 | F15: =F14/F7 | G15: =G14/G7
A17: OPERATING EXPENSES
A18: Research & Development | B18: 1871 | C18: 2182 | D18: 2553 | E18: =E7*Assumptions!$B$7 | F18: =F7*Assumptions!$C$7 | G18: =G7*Assumptions!$D$7
A19: R&D % Revenue | B19: =B18/B7 | C19: =C18/C7 | D19: =D18/D7 | E19: =E18/E7 | F19: =F18/F7 | G19: =G18/G7
A20: Sales & Marketing | B20: 1859 | C20: 2159 | D20: 2530 | E20: =E7*Assumptions!$B$8 | F20: =F7*Assumptions!$C$8 | G20: =G7*Assumptions!$D$8
A21: S&M % Revenue | B21: =B20/B7 | C21: =C20/C7 | D21: =D20/D7 | E21: =E20/E7 | F21: =F20/F7 | G21: =G20/G7
A22: General & Administrative | B22: 498 | C22: 567 | D22: 666 | E22: =E7*Assumptions!$B$9 | F22: =F7*Assumptions!$C$9 | G22: =G7*Assumptions!$D$9
A23: G&A % Revenue | B23: =B22/B7 | C23: =C22/C7 | D23: =D22/D7 | E23: =E22/E7 | F23: =F22/F7 | G23: =G22/G7
A24: Total Operating Expenses | B24: =B18+B20+B22 | C24: =C18+C20+C22 | D24: =D18+D20+D22 | E24: =E18+E20+E22 | F24: =F18+F20+F22 | G24: =G18+G20+G22
A26: Operating Income (EBIT) | B26: =B14-B24 | C26: =C14-C24 | D26: =D14-D24 | E26: =E14-E24 | F26: =F14-F24 | G26: =G14-G24
A27: EBIT Margin % | B27: =B26/B7 | C27: =C26/C7 | D27: =D26/D7 | E27: =E26/E7 | F27: =F26/F7 | G27: =G26/G7
A29: OTHER INCOME / EXPENSE
A30: Interest Income | B30: 93 | C30: 272 | D30: 478 | E30: 478 | F30: 478 | G30: 478
A31: Interest Expense | B31: -58 | C31: -63 | D31: -69 | E31: =Debt!E14 | F31: =Debt!F14 | G31: =Debt!G14
A32: Other Income (Expense) | B32: 30 | C32: -23 | D32: -47 | E32: 0 | F32: 0 | G32: 0
A33: Total Other Income (Expense) | B33: =B30+B31+B32 | C33: =C30+C31+C32 | D33: =D30+D31+D32 | E33: =E30+E31+E32 | F33: =F30+F31+F32 | G33: =G30+G31+G32
A35: Pre-Tax Income | B35: =B26+B33 | C35: =C26+C33 | D35: =D26+D33 | E35: =E26+E33 | F35: =F26+F33 | G35: =G26+G33
A37: Income Tax Provision | B37: 67 | C37: 216 | D37: 390 | E37: =E35*Assumptions!$B$10 | F37: =F35*Assumptions!$C$10 | G37: =G35*Assumptions!$D$10
A38: Effective Tax Rate % | B38: =B37/B35 | C38: =C37/C35 | D38: =D37/D35 | E38: =E37/E35 | F38: =F37/F35 | G38: =G37/G35
A40: Net Income | B40: =B35-B37 | C40: =C35-C37 | D40: =D35-D37 | E40: =E35-E37 | F40: =F35-F37 | G40: =G35-G37
A41: Net Income Margin % | B41: =B40/B7 | C41: =C40/C7 | D41: =D40/D7 | E41: =E40/E7 | F41: =F40/F7 | G41: =G40/G7
A43: MEMO ITEMS
A44: Depreciation & Amortization | B44: 513 | C44: 613 | D44: 750 | E44: =E7*Assumptions!$B$11 | F44: =F7*Assumptions!$C$11 | G44: =G7*Assumptions!$D$11
A45: D&A % Revenue | B45: =B44/B7 | C45: =C44/C7 | D45: =D44/D7 | E45: =E44/E7 | F45: =F44/F7 | G45: =G44/G7
A46: Stock-Based Compensation | B46: 1100 | C46: 1284 | D46: 1518 | E46: =E7*Assumptions!$B$12 | F46: =F7*Assumptions!$C$12 | G46: =G7*Assumptions!$D$12
A47: SBC % Revenue | B47: =B46/B7 | C47: =C46/C7 | D47: =D46/D7 | E47: =E46/E7 | F47: =F46/F7 | G47: =G46/G7
A49: EBITDA | B49: =B26+B44 | C49: =C26+C44 | D49: =D26+D44 | E49: =E26+E44 | F49: =F26+F44 | G49: =G26+G44
...

Sheet BS
A1: SERVICENOW (NOW) — BALANCE SHEET
A2: ($ in millions)
B3: FY2022A | C3: FY2023A | D3: FY2024A | E3: FY2025E | F3: FY2026E | G3: FY2027E
A4: ASSETS
A5: CURRENT ASSETS
A6: Cash & Cash Equivalents | B6: 1488 | C6: 1946 | D6: 3000 | E6: =CF!E30 | F6: =CF!F30 | G6: =CF!G30
A7: Short-Term Investments | B7: 2012 | C7: 2634 | D7: 2900 | E7: =D7*(1+Assumptions!$B$5*0.5) | F7: =E7*(1+Assumptions!$C$5*0.5) | G7: =F7*(1+Assumptions!$D$5*0.5)
A8: Accounts Receivable, net | B8: 1474 | C8: 1852 | D8: 2290 | E8: =WC!E8 | F8: =WC!F8 | G8: =WC!G8
A9: Deferred Commissions (ST) | B9: 385 | C9: 432 | D9: 510 | E9: =E8*(510/2290) | F9: =F8*(510/2290) | G9: =G8*(510/2290)
A10: Prepaid & Other Current Assets | B10: 432 | C10: 498 | D10: 580 | E10: =D10*1.10 | F10: =E10*1.10 | G10: =F10*1.10
A11: Total Current Assets | B11: =SUM(B6:B10) | C11: =SUM(C6:C10) | D11: =SUM(D6:D10) | E11: =SUM(E6:E10) | F11: =SUM(F6:F10) | G11: =SUM(G6:G10)
A13: NON-CURRENT ASSETS
A14: PP&E, net | B14: 1032 | C14: 1212 | D14: 1450 | E14: =DA!E13 | F14: =DA!F13 | G14: =DA!G13
A15: Operating Lease ROU Assets | B15: 810 | C15: 789 | D15: 760 | E15: =D15*0.97 | F15: =E15*0.97 | G15: =F15*0.97
A16: Deferred Commissions (LT) | B16: 890 | C16: 1024 | D16: 1210 | E16: =E8*(1210/2290) | F16: =F8*(1210/2290) | G16: =G8*(1210/2290)
A17: Intangibles & Goodwill | B17: 2810 | C17: 3050 | D17: 3200 | E17: =D17-Assumptions!$B$24 | F17: =E17-Assumptions!$C$24 | G17: =F17-Assumptions!$D$24
A18: Other Long-Term Assets | B18: 560 | C18: 680 | D18: 750 | E18: =D18*1.05 | F18: =E18*1.05 | G18: =F18*1.05
A19: Total Non-Current Assets | B19: =SUM(B14:B18) | C19: =SUM(C14:C18) | D19: =SUM(D14:D18) | E19: =SUM(E14:E18) | F19: =SUM(F14:F18) | G19: =SUM(G14:G18)
A20: TOTAL ASSETS | B20: =B11+B19 | C20: =C11+C19 | D20: =D11+D19 | E20: =E11+E19 | F20: =F11+F19 | G20: =G11+G19
A22: LIABILITIES
A23: CURRENT LIABILITIES
A24: Accounts Payable | B24: 156 | C24: 187 | D24: 220 | E24: =WC!E15 | F24: =WC!F15 | G24: =WC!G15
A25: Accrued Expenses | B25: 980 | C25: 1150 | D25: 1380 | E25: =IS!E7*0.115 | F25: =IS!F7*0.115 | G25: =IS!G7*0.115
A26: Deferred Revenue (ST) | B26: 4073 | C26: 4851 | D26: 5810 | E26: =D26*(1+Assumptions!$B$5*0.95) | F26: =E26*(1+Assumptions!$C$5*0.95) | G26: =F26*(1+Assumptions!$D$5*0.95)
A27: Current Portion of Long-Term Debt | B27: 1500 | C27: 0 | D27: 0 | E27: =Debt!E10 | F27: =Debt!F10 | G27: =Debt!G10
A28: Total Current Liabilities | B28: =SUM(B24:B27) | C28: =SUM(C24:C27) | D28: =SUM(D24:D27) | E28: =SUM(E24:E27) | F28: =SUM(F24:F27) | G28: =SUM(G24:G27)
A30: LONG-TERM LIABILITIES
A31: Deferred Revenue (LT) | B31: 180 | C31: 212 | D31: 255 | E31: =D31*1.10 | F31: =E31*1.10 | G31: =F31*1.10
A32: Long-Term Debt | B32: 1489 | C32: 1490 | D32: 1490 | E32: =Debt!E11 | F32: =Debt!F11 | G32: =Debt!G11
A33: Operating Lease Liabilities (LT) | B33: 791 | C33: 766 | D33: 740 | E33: =D33*0.97 | F33: =E33*0.97 | G33: =F33*0.97
A34: Other Long-Term Liabilities | B34: 210 | C34: 287 | D34: 350 | E34: =D34*1.08 | F34: =E34*1.08 | G34: =F34*1.08
A35: Total Long-Term Liabilities | B35: =SUM(B31:B34) | C35: =SUM(C31:C34) | D35: =SUM(D31:D34) | E35: =SUM(E31:E34) | F35: =SUM(F31:F34) | G35: =SUM(G31:G34)
A36: Total Liabilities | B36: =B28+B35 | C36: =C28+C35 | D36: =D28+D35 | E36: =E28+E35 | F36: =F28+F35 | G36: =G28+G35
A38: STOCKHOLDERS' EQUITY
A39: Common Stock & Additional Paid-In Capital | B39: 8800 | C39: 10350 | D39: 12100 | E39: =D39+IS!E46+Assumptions!$B$23 | F39: =E39+IS!F46+Assumptions!$C$23 | G39: =F39+IS!G46+Assumptions!$D$23
A40: Retained Earnings (Deficit) | B40: -2450 | C40: -2270 | D40: -1850 | E40: =D40+IS!E40+Assumptions!$B$22 | F40: =E40+IS!F40+Assumptions!$C$22 | G40: =F40+IS!G40+Assumptions!$D$22
A41: Accumulated Other Comprehensive Loss | B41: -120 | C41: -135 | D41: -115 | E41: =D41 | F41: =E41 | G41: =F41
A42: Total Stockholders' Equity | B42: =SUM(B39:B41) | C42: =SUM(C39:C41) | D42: =SUM(D39:D41) | E42: =SUM(E39:E41) | F42: =SUM(F39:F41) | G42: =SUM(G39:G41)
A43: TOTAL LIABILITIES & EQUITY | B43: =B36+B42 | C43: =C36+C42 | D43: =D36+D42 | E43: =E36+E42 | F43: =F36+F42 | G43: =G36+G42

Sheet CF
A1: SERVICENOW (NOW) — CASH FLOW STATEMENT
A2: ($ in millions)
B3: FY2022A | C3: FY2023A | D3: FY2024A | E3: FY2025E | F3: FY2026E | G3: FY2027E
A4: OPERATING ACTIVITIES
A5: Net Income | B5: =IS!B40 | C5: =IS!C40 | D5: =IS!D40 | E5: =IS!E40 | F5: =IS!F40 | G5: =IS!G40
A6: Depreciation & Amortization | B6: =IS!B44 | C6: =IS!C44 | D6: =IS!D44 | E6: =IS!E44 | F6: =IS!F44 | G6: =IS!G44
A7: Stock-Based Compensation | B7: =IS!B46 | C7: =IS!C46 | D7: =IS!D46 | E7: =IS!E46 | F7: =IS!F46 | G7: =IS!G46
A8: Change in Accounts Receivable | B8: -297 | C8: -378 | D8: -438 | E8: =-(WC!E8-WC!D8) | F8: =-(WC!F8-WC!E8) | G8: =-(WC!G8-WC!F8)
A9: Change in Deferred Revenue | B9: 721 | C9: 810 | D9: 1002 | E9: =(BS!E26+BS!E31)-(BS!D26+BS!D31) | F9: =(BS!F26+BS!F31)-(BS!E26+BS!E31) | G9: =(BS!G26+BS!G31)-(BS!F26+BS!F31)
A10: Change in Accounts Payable & Accrued Exp. | B10: 180 | C10: 201 | D10: 263 | E10: =(WC!E15-WC!D15)+(BS!E25-BS!D25) | F10: =(WC!F15-WC!E15)+(BS!F25-BS!E25) | G10: =(WC!G15-WC!F15)+(BS!G25-BS!F25)
A11: Change in Other Working Capital | B11: 50 | C11: -30 | D11: -20 | E11: =-(BS!E10-BS!D10)*0.5 | F11: =-(BS!F10-BS!E10)*0.5 | G11: =-(BS!G10-BS!F10)*0.5
A13: Cash from Operations (CFO) | B13: =SUM(B5:B11) | C13: =SUM(C5:C11) | D13: =SUM(D5:D11) | E13: =SUM(E5:E11) | F13: =SUM(F5:F11) | G13: =SUM(G5:G11)
A14: CFO Margin % | B14: =B13/IS!B7 | C14: =C13/IS!C7 | D14: =D13/IS!D7 | E14: =E13/IS!E7 | F14: =F13/IS!F7 | G14: =G13/IS!G7
A16: INVESTING ACTIVITIES
A17: Capital Expenditures | B17: -502 | C17: -592 | D17: -680 | E17: =-IS!E7*Assumptions!$B$15 | F17: =-IS!F7*Assumptions!$C$15 | G17: =-IS!G7*Assumptions!$D$15
A18: Acquisitions | B18: -420 | C18: -610 | D18: -285 | E18: =Assumptions!$B$24 | F18: =Assumptions!$C$24 | G18: =Assumptions!$D$24
A19: Net Investment Purchases / (Sales) | B19: -580 | C19: -730 | D19: -310 | E19: =Assumptions!$B$25 | F19: =Assumptions!$C$25 | G19: =Assumptions!$D$25
A20: Cash from Investing (CFI) | B20: =SUM(B17:B19) | C20: =SUM(C17:C19) | D20: =SUM(D17:D19) | E20: =SUM(E17:E19) | F20: =SUM(F17:F19) | G20: =SUM(G17:G19)
A22: FINANCING ACTIVITIES
A23: Share Repurchases | B23: -1200 | C23: -1500 | D23: -1800 | E23: =Assumptions!$B$22 | F23: =Assumptions!$C$22 | G23: =Assumptions!$D$22
A24: Proceeds from ESPP / Options | B24: 300 | C24: 380 | D24: 450 | E24: =Assumptions!$B$23 | F24: =Assumptions!$C$23 | G24: =Assumptions!$D$23
A25: Debt Repayment | B25: -1500 | C25: 0 | D25: 0 | E25: =Debt!E7 | F25: =Debt!F7 | G25: =Debt!G7
A26: Cash from Financing (CFF) | B26: =SUM(B23:B25) | C26: =SUM(C23:C25) | D26: =SUM(D23:D25) | E26: =SUM(E23:E25) | F26: =SUM(F23:F25) | G26: =SUM(G23:G25)
A28: Net Change in Cash | B28: =B13+B20+B26 | C28: =C13+C20+C26 | D28: =D13+D20+D26 | E28: =E13+E20+E26 | F28: =F13+F20+F26 | G28: =G13+G20+G26
A29: Beginning Cash | B29: 1239 | C29: =B30 | D29: =C30 | E29: =D30 | F29: =E30 | G29: =F30
A30: Ending Cash | B30: =B29+B28 | C30: =C29+C28 | D30: =D29+D28 | E30: =E29+E28 | F30: =F29+F28 | G30: =G29+G28
A32: Free Cash Flow (memo) | B32: =B13+B17 | C32: =C13+C17 | D32: =D13+D17 | E32: =E13+E17 | F32: =F13+F17 | G32: =G13+G17
A33: FCF Margin % | B33: =B32/IS!B7 | C33: =C32/IS!C7 | D33: =D32/IS!D7 | E33: =E32/IS!E7 | F33: =F32/IS!F7 | G33: =G32/IS!G7

Sheet WC
A1: WORKING CAPITAL SCHEDULE
A2: ($ in millions)
B3: FY2022A | C3: FY2023A | D3: FY2024A | E3: FY2025E | F3: FY2026E | G3: FY2027E
A4: ACCOUNTS RECEIVABLE
A5: Beginning AR | B5: 1177 | C5: =B8 | D5: =C8 | E5: =D8 | F5: =E8 | G5: =F8
A6: Revenue (ref) | B6: =IS!B7 | C6: =IS!C7 | D6: =IS!D7 | E6: =IS!E7 | F6: =IS!F7 | G6: =IS!G7
A7: Cash Collections (plug) | B7: =B5+B6-B8 | C7: =C5+C6-C8 | D7: =D5+D6-D8 | E7: =E5+E6-E8 | F7: =F5+F6-F8 | G7: =G5+G6-G8
A8: Ending AR | B8: 1474 | C8: 1852 | D8: 2290 | E8: =IS!E7*Assumptions!$B$18/365 | F8: =IS!F7*Assumptions!$C$18/365 | G8: =IS!G7*Assumptions!$D$18/365
A9: DSO (days) | B9: =B8/B6*365 | C9: =C8/C6*365 | D9: =D8/D6*365 | E9: =E8/E6*365 | F9: =F8/F6*365 | G9: =G8/G6*365
A11: ACCOUNTS PAYABLE
A12: Beginning AP | B12: 125 | C12: =B15 | D12: =C15 | E12: =D15 | F12: =E15 | G12: =F15
A13: Cost of Revenue (COGS proxy) | B13: =IS!B13 | C13: =IS!C13 | D13: =IS!D13 | E13: =IS!E13 | F13: =IS!F13 | G13: =IS!G13
A14: Cash Payments (plug) | B14: =B12+B13-B15 | C14: =C12+C13-C15 | D14: =D12+D13-D15 | E14: =E12+E13-E15 | F14: =F12+F13-F15 | G14: =G12+G13-G15
A15: Ending AP | B15: 156 | C15: 187 | D15: 220 | E15: =IS!E13*Assumptions!$B$19/365 | F15: =IS!F13*Assumptions!$C$19/365 | G15: =IS!G13*Assumptions!$D$19/365
A16: DPO (days) | B16: =B15/B13*365 | C16: =C15/C13*365 | D16: =D15/D13*365 | E16: =E15/E13*365 | F16: =F15/F13*365 | G16: =G15/G13*365

Sheet DA
A1: D&A / PP&E SCHEDULE
A2: ($ in millions)
B3: FY2022A | C3: FY2023A | D3: FY2024A | E3: FY2025E | F3: FY2026E | G3: FY2027E
A4: PP&E ROLL-FORWARD
A5: Beginning PP&E (Gross) | B5: 1800 | C5: =B7 | D5: =C7 | E5: =D7 | F5: =E7 | G5: =F7
A6: Capital Expenditures | B6: 502 | C6: 592 | D6: 680 | E6: =-CF!E17 | F6: =-CF!F17 | G6: =-CF!G17
A7: Ending PP&E (Gross) | B7: =B5+B6 | C7: =C5+C6 | D7: =D5+D6 | E7: =E5+E6 | F7: =F5+F6 | G7: =G5+G6
A9: Beginning Accumulated Depreciation | B9: 760 | C9: =B11 | D9: =C11 | E9: =D11 | F9: =E11 | G9: =F11
A10: Depreciation Expense | B10: =IS!B44 | C10: =IS!C44 | D10: =IS!D44 | E10: =IS!E44 | F10: =IS!F44 | G10: =IS!G44
A11: Ending Accumulated Depreciation | B11: =B9+B10 | C11: =C9+C10 | D11: =D9+D10 | E11: =E9+E10 | F11: =F9+F10 | G11: =G9+G10
A13: PP&E, Net | B13: =B7-B11 | C13: =C7-C11 | D13: =D7-D11 | E13: =E7-E11 | F13: =F7-F11 | G13: =G7-G11

Sheet Debt
A1: DEBT SCHEDULE
A2: ($ in millions)
B3: FY2022A | C3: FY2023A | D3: FY2024A | E3: FY2025E | F3: FY2026E | G3: FY2027E
A4: TOTAL DEBT ROLL-FORWARD
A5: Beginning Total Debt | B5: 3000 | C5: =B8 | D5: =C8 | E5: =D8 | F5: =E8 | G5: =F8
A6: New Borrowings | B6: 0 | C6: 0 | D6: 0 | E6: 0 | F6: 0 | G6: 0
A7: Debt Repayments | B7: -1500 | C7: 0 | D7: 0 | E7: 0 | F7: 0 | G7: 0
A8: Ending Total Debt | B8: =B5+B6+B7 | C8: =C5+C6+C7 | D8: =D5+D6+D7 | E8: =E5+E6+E7 | F8: =F5+F6+F7 | G8: =G5+G6+G7
A10: Current Portion of LTD | B10: 1500 | C10: 0 | D10: 0 | E10: 0 | F10: 0 | G10: 0
A11: Long-Term Debt | B11: =B8-B10 | C11: =C8-C10 | D11: =D8-D10 | E11: =E8-E10 | F11: =F8-F10 | G11: =G8-G10
A13: INTEREST EXPENSE
A14: Interest Rate | B14: 0.045 | C14: 0.045 | D14: 0.045 | E14: 0.045 | F14: 0.045 | G14: 0.045
A15: Interest Expense | B15: =-B5*B14 | C15: =-C5*C14 | D15: =-D5*D14 | E15: =-E5*E14 | F15: =-F5*F14 | G15: =-G5*G14

Sheet Assumptions
A1: SERVICENOW (NOW) — MODEL ASSUMPTIONS
A2: ($ in millions, unless noted)
B3: FY2025E | C3: FY2026E | D3: FY2027E
A4: INCOME STATEMENT DRIVERS
A5: Revenue Growth Rate (Memo) | B5: 0.22 | C5: 0.19 | D5: 0.17
A6: Gross Margin % | B6: 0.795 | C6: 0.8 | D6: 0.805
A7: R&D % of Revenue | B7: 0.23 | C7: 0.225 | D7: 0.22
A8: S&M % of Revenue | B8: 0.22 | C8: 0.215 | D8: 0.21
A9: G&A % of Revenue | B9: 0.06 | C9: 0.058 | D9: 0.056
A10: Tax Rate | B10: 0.18 | C10: 0.18 | D10: 0.18
A11: D&A % of Revenue | B11: 0.07 | C11: 0.068 | D11: 0.065
A12: SBC % of Revenue | B12: 0.135 | C12: 0.13 | D12: 0.125
A14: CASH FLOW & CAPEX DRIVERS
A15: Capex % of Revenue | B15: 0.065 | C15: 0.062 | D15: 0.06
A17: WORKING CAPITAL DRIVERS
A18: DSO (days) | B18: 75 | C18: 74 | D18: 73
A19: DPO (days) | B19: 32 | C19: 32 | D19: 32
A21: FINANCING ASSUMPTIONS
A22: Share Repurchases ($M) | B22: -1800 | C22: -1900 | D22: -2000
A23: ESPP / Options Proceeds ($M) | B23: 500 | C23: 530 | D23: 560
A24: Net Acquisitions ($M) | B24: -300 | C24: -300 | D24: -300
A25: Net Investment Purchases ($M) | B25: -350 | C25: -350 | D25: -350
A27: SOFTWARE REVENUE DRIVERS
A29: ARR BRIDGE ASSUMPTIONS
A30: Primary Methodology: ARR Bridge
A34: New Logo ARR Growth % YoY | B34: 0.2 | C34: 0.18 | D34: 0.16
A35: Expansion Rate (% of Beginning ARR) | B35: 0.24 | C35: 0.23 | D35: 0.22
A36: Gross Revenue Retention (GRR) % | B36: 0.99 | C36: 0.99 | D36: 0.99
A37: Contraction Rate (% of Beginning ARR) | B37: 0.003 | C37: 0.003 | D37: 0.003
A38: Billing Timing Factor | B38: 0.98 | C38: 0.98 | D38: 0.98
A40: RETENTION-BASED ASSUMPTIONS
A41: Net Revenue Retention (NRR) % | B41: 1.24 | C41: 1.23 | D41: 1.22
A42: Logo Churn Rate % | B42: 0.03 | C42: 0.03 | D42: 0.03
A44: CUSTOMER TIER GROWTH
A45: Customers >$1M ACV Growth % | B45: 0.2 | C45: 0.18 | D45: 0.16
A46: Customers >$5M ACV Growth % | B46: 0.18 | C46: 0.16 | D46: 0.15
A47: Customers >$20M ACV Growth % | B47: 0.15 | C47: 0.14 | D47: 0.13
A49: RPO ASSUMPTIONS
A50: cRPO Recognition Rate (next 12 months) | B50: 0.94 | C50: 0.94 | D50: 0.94
A51: Total RPO Growth % | B51: 0.18 | C51: 0.16 | D51: 0.14
...

Sheet Checks
A1: MODEL INTEGRITY CHECKS — SERVICENOW
A2: GREEN = pass (TRUE), RED = fail (FALSE). Historical BS checks may show small discrepancies from rounded inputs.
A3: Check | B3: Expected | C3: Note | D3: Result | E3: Status
A5: BALANCE SHEET — Assets = Liabilities + Equity
A6: BS Balances — FY2022A | B6: 0 | C6: Assets - L&E | D6: =BS!B20-BS!B43 | E6: =IF(ABS(D6)<1,"TRUE","FALSE")
A7: BS Balances — FY2023A | B7: 0 | C7: Assets - L&E | D7: =BS!C20-BS!C43 | E7: =IF(ABS(D7)<1,"TRUE","FALSE")
A8: BS Balances — FY2024A | B8: 0 | C8: Assets - L&E | D8: =BS!D20-BS!D43 | E8: =IF(ABS(D8)<1,"TRUE","FALSE")
A9: BS Balances — FY2025E | B9: 0 | C9: Assets - L&E | D9: =BS!E20-BS!E43 | E9: =IF(ABS(D9)<1,"TRUE","FALSE")
A10: BS Balances — FY2026E | B10: 0 | C10: Assets - L&E | D10: =BS!F20-BS!F43 | E10: =IF(ABS(D10)<1,"TRUE","FALSE")
A11: BS Balances — FY2027E | B11: 0 | C11: Assets - L&E | D11: =BS!G20-BS!G43 | E11: =IF(ABS(D11)<1,"TRUE","FALSE")
A13: CASH TIE-OUT — CF Ending Cash = BS Cash
A14: CF Cash = BS Cash — FY2022A | B14: 0 | C14: CF end - BS cash | D14: =CF!B30-BS!B6 | E14: =IF(ABS(D14)<1,"TRUE","FALSE")
A15: CF Cash = BS Cash — FY2023A | B15: 0 | C15: CF end - BS cash | D15: =CF!C30-BS!C6 | E15: =IF(ABS(D15)<1,"TRUE","FALSE")
A16: CF Cash = BS Cash — FY2024A | B16: 0 | C16: CF end - BS cash | D16: =CF!D30-BS!D6 | E16: =IF(ABS(D16)<1,"TRUE","FALSE")
A17: CF Cash = BS Cash — FY2025E | B17: 0 | C17: CF end - BS cash | D17: =CF!E30-BS!E6 | E17: =IF(ABS(D17)<1,"TRUE","FALSE")
A18: CF Cash = BS Cash — FY2026E | B18: 0 | C18: CF end - BS cash | D18: =CF!F30-BS!F6 | E18: =IF(ABS(D18)<1,"TRUE","FALSE")
A19: CF Cash = BS Cash — FY2027E | B19: 0 | C19: CF end - BS cash | D19: =CF!G30-BS!G6 | E19: =IF(ABS(D19)<1,"TRUE","FALSE")
A21: NET INCOME LINK — IS = CF
A22: IS NI = CF NI — FY2022A | B22: 0 | C22: IS row 40 - CF row 5 | D22: =IS!B40-CF!B5 | E22: =IF(ABS(D22)<1,"TRUE","FALSE")
A23: IS NI = CF NI — FY2024A | B23: 0 | C23: IS row 40 - CF row 5 | D23: =IS!D40-CF!D5 | E23: =IF(ABS(D23)<1,"TRUE","FALSE")
A24: IS NI = CF NI — FY2025E | B24: 0 | C24: IS row 40 - CF row 5 | D24: =IS!E40-CF!E5 | E24: =IF(ABS(D24)<1,"TRUE","FALSE")
A25: IS NI = CF NI — FY2026E | B25: 0 | C25: IS row 40 - CF row 5 | D25: =IS!F40-CF!F5 | E25: =IF(ABS(D25)<1,"TRUE","FALSE")
A26: IS NI = CF NI — FY2027E | B26: 0 | C26: IS row 40 - CF row 5 | D26: =IS!G40-CF!G5 | E26: =IF(ABS(D26)<1,"TRUE","FALSE")
A28: PP&E NET — DA Schedule = BS
A29: DA PP&E Net = BS PP&E — FY2024A | B29: 0 | C29: DA row 13 - BS row 14 | D29: =DA!D13-BS!D14 | E29: =IF(ABS(D29)<1,"TRUE","FALSE")
A30: DA PP&E Net = BS PP&E — FY2025E | B30: 0 | C30: DA row 13 - BS row 14 | D30: =DA!E13-BS!E14 | E30: =IF(ABS(D30)<1,"TRUE","FALSE")
A31: DA PP&E Net = BS PP&E — FY2026E | B31: 0 | C31: DA row 13 - BS row 14 | D31: =DA!F13-BS!F14 | E31: =IF(ABS(D31)<1,"TRUE","FALSE")
A32: DA PP&E Net = BS PP&E — FY2027E | B32: 0 | C32: DA row 13 - BS row 14 | D32: =DA!G13-BS!G14 | E32: =IF(ABS(D32)<1,"TRUE","FALSE")
A34: RETAINED EARNINGS ROLL-FORWARD
A35: RE Roll-Fwd — FY2025E | B35: 0 | C35: RE = prior + NI + buybacks | D35: =BS!E40-(BS!D40+IS!E40+Assumptions!$B$22) | E35: =IF(ABS(D35)<1,"TRUE","FALSE")
A36: RE Roll-Fwd — FY2026E | B36: 0 | C36: RE = prior + NI + buybacks | D36: =BS!F40-(BS!E40+IS!F40+Assumptions!$C$22) | E36: =IF(ABS(D36)<1,"TRUE","FALSE")
A37: RE Roll-Fwd — FY2027E | B37: 0 | C37: RE = prior + NI + buybacks | D37: =BS!G40-(BS!F40+IS!G40+Assumptions!$D$22) | E37: =IF(ABS(D37)<1,"TRUE","FALSE")
A40: SOFTWARE — IS REVENUE LINKS (revenue_build → IS)
A41: IS Sub Rev = rb Sub Rev — FY2025E | B41: 0 | C41: IS row 5 = rb row 37 | D41: =IS!E5-revenue_build!E37 | E41: =IF(ABS(D41)<0.01,"TRUE","FALSE")
A42: IS Sub Rev = rb Sub Rev — FY2026E | B42: 0 | C42: IS row 5 = rb row 37 | D42: =IS!F5-revenue_build!F37 | E42: =IF(ABS(D42)<0.01,"TRUE","FALSE")
A43: IS Sub Rev = rb Sub Rev — FY2027E | B43: 0 | C43: IS row 5 = rb row 37 | D43: =IS!G5-revenue_build!G37 | E43: =IF(ABS(D43)<0.01,"TRUE","FALSE")
A44: IS PS Rev = rb PS Rev — FY2025E | B44: 0 | C44: IS row 6 = rb row 38 | D44: =IS!E6-revenue_build!E38 | E44: =IF(ABS(D44)<0.01,"TRUE","FALSE")
A45: IS PS Rev = rb PS Rev — FY2026E | B45: 0 | C45: IS row 6 = rb row 38 | D45: =IS!F6-revenue_build!F38 | E45: =IF(ABS(D45)<0.01,"TRUE","FALSE")
A46: IS PS Rev = rb PS Rev — FY2027E | B46: 0 | C46: IS row 6 = rb row 38 | D46: =IS!G6-revenue_build!G38 | E46: =IF(ABS(D46)<0.01,"TRUE","FALSE")
A48: SOFTWARE — ARR BRIDGE & KPI CHECKS
...
